<?xml version="1.0" encoding="utf-8"?>
<!-- =================================================================================== -->
<!-- |    This document was autogenerated by xacro from pioneer3at.urdf.xacro          | -->
<!-- |    EDITING THIS FILE BY HAND IS NOT RECOMMENDED                                 | -->
<!-- =================================================================================== -->
<robot name="pioneer3at" xmlns:controller="http://playerstage.sourceforge.net/gazebo/xmlschema/#controller" xmlns:interface="http://playerstage.sourceforge.net/gazebo/xmlschema/#interface" xmlns:sensor="http://playerstage.sourceforge.net/gazebo/xmlschema/#sensor">
  <material name="SonarYellow">
    <color rgba="0.715 0.583 0.210 1.0"/>
  </material>
  <material name="WheelBlack">
    <color rgba="0.117 0.117 0.117 1.0"/>
  </material>
  <material name="HubcapYellow">
    <color rgba="1.0 0.811 0.151 1.0"/>
  </material>
  <material name="ChassisRed">
    <color rgba="0.8 0.0 0.0 1.0"/>
  </material>
  <material name="TopBlack">
    <color rgba="0.038 0.038 0.038 1.0"/>
  </material>
  <material name="ChassisGrey">
    <color rgba="0.47 0.47 0.47 1.0"/>
  </material>
  <!-- Chassis -->
  <link name="base_link">
    <!--  For pointers on inertial and gazebo-related parameters see
		       * http://wiki.ros.org/urdf/Tutorials/Adding%20Physical%20and%20Collision%20Properties%20to%20a%20URDF%20Model
                       * http://answers.gazebosim.org/question/4372/the-inertia-matrix-explained/
		       * http://gazebosim.org/tutorials?tut=inertia&cat=build_robot, and 
                       * http://gazebosim.org/tutorials/?tut=ros_urdf
                       * http://en.wikipedia.org/wiki/List_of_moment_of_inertia_tensors  
                -->
    <inertial>
      <mass value="21.5"/>
      <!-- P3AT 18.6kg plus three batteries @ 2.4kg each  minus four wheels @ 1.4 kg ea and top plate @ 0.1 kg-->
      <origin xyz="-0.1 0 0.177"/>
      <inertia ixx="0.3338" ixy="0.0" ixz="0.0" iyy="0.4783" iyz="0.0" izz="0.3338"/>
    </inertial>
    <visual>
      <origin rpy="0 0 0" xyz="0 0 0.177"/>
      <geometry name="pioneer_geom">
        <mesh filename="package://yeetbot_navigation/meshes/chassis.stl"/>
      </geometry>
      <material name="ChassisRed">
        <color rgba="0.851 0.0 0.0 1.0"/>
      </material>
    </visual>
    <collision>
      <origin rpy="0 0 0" xyz="0 0 0.177"/>
      <geometry>
        <mesh filename="package://yeetbot_navigation/meshes/chassis.stl"/>
      </geometry>
    </collision>
  </link>
  <gazebo reference="base_link">
    <material value="Gazebo/Red"/>
  </gazebo>
  <!-- Top -->
  <link name="top_plate">
    <inertial>
      <mass value="0.1"/>
      <origin xyz="-0.025 0 -0.223"/>
      <inertia ixx="1.0" ixy="0.0" ixz="0.0" iyy="1.0" iyz="0.0" izz="1.0"/>
    </inertial>
    <visual>
      <origin rpy="0 0 0" xyz="0 0 0"/>
      <geometry name="pioneer_geom">
        <mesh filename="package://yeetbot_navigation/meshes/top.stl"/>
      </geometry>
      <material name="TopBlack">
        <color rgba="0.038 0.038 0.038 1.0"/>
      </material>
    </visual>
  </link>
  <gazebo reference="top_plate">
    <material>Gazebo/Black</material>
  </gazebo>
  <joint name="base_top_joint" type="fixed">
    <origin rpy="0 0 0" xyz="0.003 0 0.274"/>
    <parent link="base_link"/>
    <child link="top_plate"/>
  </joint>
  <!-- Drawer Frame -->
  <link name="drawer_frame">
    <inertial>
      <mass value="3.0"/>
      <origin xyz="-0.025 0 -0.223"/>
      <inertia ixx="1.0" ixy="0.0" ixz="0.0" iyy="1.0" iyz="0.0" izz="1.0"/>
    </inertial>
    <visual>
      <origin rpy="0 0 0" xyz="0 0 0"/>
      <geometry name="pioneer_geom">
        <mesh filename="package://yeetbot_navigation/meshes/drawer_frame_part.STL" scale="0.001 0.001 0.001"/>
      </geometry>
      <material name="TopBlack">
        <color rgba="0.038 0.038 0.038 1.0"/>
      </material>
    </visual>
    <collision>
      <origin rpy="0 0 0" xyz="-0.025 0 -0.223"/>
      <geometry>
        <mesh filename="package://yeetbot_navigation/meshes/drawer_frame_part.STL" scale="0.001 0.001 0.001"/>
      </geometry>
    </collision>
  </link>
  <gazebo reference="drawer_frame">
    <material>Gazebo/Black</material>
  </gazebo>
  <joint name="top_drawer_joint" type="fixed">
    <origin rpy="1.570795 0 4.712385" xyz="0.25 0.122 0.003"/>
    <parent link="top_plate"/>
    <child link="drawer_frame"/>
  </joint>
  <!-- Front + Back Sonar -->
  <link name="front_sonar">
    <inertial>
      <mass value="0.1"/>
      <origin xyz="0 0 0"/>
      <inertia ixx="1.0" ixy="0.0" ixz="0.0" iyy="1.0" iyz="0.0" izz="1.0"/>
    </inertial>
    <visual>
      <origin rpy="0 0 0" xyz="0 0 0"/>
      <geometry name="pioneer_geom">
        <mesh filename="package://yeetbot_navigation/meshes/front_sonar.stl"/>
      </geometry>
      <material name="SonarYellow">
        <color rgba="0.715 0.583 0.210 1.0"/>
      </material>
    </visual>
  </link>
  <gazebo reference="front_sonar">
    <material value="Gazebo/Yellow"/>
  </gazebo>
  <joint name="base_front_joint" type="fixed">
    <origin rpy="0 0 0" xyz="0.193 0 0.25"/>
    <parent link="base_link"/>
    <child link="front_sonar"/>
  </joint>
  <link name="back_sonar">
    <inertial>
      <mass value="0.1"/>
      <origin xyz="0 0 0"/>
      <inertia ixx="1.0" ixy="0.0" ixz="0.0" iyy="1.0" iyz="0.0" izz="1.0"/>
    </inertial>
    <visual>
      <origin rpy="0 0 0" xyz="0 0 0"/>
      <geometry name="pioneer_geom">
        <mesh filename="package://yeetbot_navigation/meshes/back_sonar.stl"/>
      </geometry>
      <material name="SonarYellow">
        <color rgba="0.715 0.583 0.210 1.0"/>
      </material>
    </visual>
  </link>
  <gazebo reference="back_sonar">
    <material value="Gazebo/Yellow"/>
  </gazebo>
  <joint name="base_back_joint" type="fixed">
    <origin rpy="0 0 0" xyz="-0.187 0 0.247"/>
    <parent link="base_link"/>
    <child link="back_sonar"/>
  </joint>
  <!-- Kinect Depth Sensor  -->
  <link name="kinect_link">
    <visual>
      <geometry>
        <box size="0.064 0.121 0.0381"/>
      </geometry>
      <material name="Blue"/>
    </visual>
    <inertial>
      <mass value="0.0001"/>
      <origin xyz="0 0 0"/>
      <inertia ixx="0.0001" ixy="0.0" ixz="0.0" iyy="0.0001" iyz="0.0" izz="0.0001"/>
    </inertial>
  </link>
  <joint name="base_kinect_joint" type="fixed">
    <origin rpy="0 0 0" xyz="0.2 0 1.193"/>
    <parent link="base_link"/>
    <child link="kinect_link"/>
  </joint>
  <link name="kinect_depth_frame">
    <inertial>
      <mass value="0.0001"/>
      <origin xyz="0 0 0"/>
      <inertia ixx="0.0001" ixy="0.0" ixz="0.0" iyy="0.0001" iyz="0.0" izz="0.0001"/>
    </inertial>
  </link>
  <joint name="kinect_depth_joint" type="fixed">
    <origin rpy="0 0 0" xyz="0 0.028 0"/>
    <parent link="kinect_link"/>
    <child link="kinect_depth_frame"/>
  </joint>
  <link name="kinect_depth_optical_frame">
    <inertial>
      <mass value="0.0001"/>
      <origin xyz="0 0 0"/>
      <inertia ixx="0.0001" ixy="0.0" ixz="0.0" iyy="0.0001" iyz="0.0" izz="0.0001"/>
    </inertial>
  </link>
  <joint name="depth_optical_joint" type="fixed">
    <origin rpy="1.570795 0 1.570795" xyz="0 0 0"/>
    <parent link="kinect_depth_frame"/>
    <child link="kinect_depth_optical_frame"/>
  </joint>
  <!-- Hokuyo LIDAR -->
  <link name="lidar_link">
    <visual>
      <geometry>
        <box size="0.05 0.05 0.07"/>
      </geometry>
      <material name="Green"/>
    </visual>
  </link>
  <joint name="base_lidar_joint" type="fixed">
    <origin rpy="0 0 0" xyz="0.285 0 0.235"/>
    <parent link="base_link"/>
    <child link="lidar_link"/>
  </joint>
  <link name="beam_link">
    <inertial>
      <mass value="0.0001"/>
      <origin xyz="0 0 0"/>
      <inertia ixx="0.0001" ixy="0.0" ixz="0.0" iyy="0.0001" iyz="0.0" izz="0.0001"/>
    </inertial>
  </link>
  <joint name="lidar_beam_joint" type="fixed">
    <origin rpy="3.14159 0 0" xyz="0 0 -0.0225"/>
    <parent link="lidar_link"/>
    <child link="beam_link"/>
  </joint>
  <!-- Front Axles + Wheels + Hubcaps -->
  <link name="p3at_front_left_axle">
    <inertial>
      <mass value="0.1"/>
      <origin xyz="0 0 0"/>
      <inertia ixx="1.0" ixy="0.0" ixz="0.0" iyy="1.0" iyz="0.0" izz="1.0"/>
    </inertial>
    <visual>
      <origin rpy="0 0 0" xyz="0 0 0"/>
      <geometry name="pioneer_geom">
        <mesh filename="package://yeetbot_navigation/meshes/axle.stl"/>
      </geometry>
      <material name="AxleGrey">
        <color rgba="0.5 0.5 0.5 1"/>
      </material>
    </visual>
  </link>
  <gazebo reference="p3at_front_left_axle">
    <material value="Gazebo/Grey"/>
  </gazebo>
  <joint name="base_front_left_axle_joint" type="fixed">
    <origin rpy="0 0 0" xyz="0.135 0.156 0.111"/>
    <parent link="base_link"/>
    <child link="p3at_front_left_axle"/>
  </joint>
  <link name="p3at_front_left_hub">
    <inertial>
      <mass value="0.1"/>
      <origin xyz="0 0 0"/>
      <inertia ixx="1.0" ixy="0.0" ixz="0.0" iyy="1.0" iyz="0.0" izz="1.0"/>
    </inertial>
    <visual>
      <origin rpy="0 0 0" xyz="0 0 0"/>
      <geometry name="pioneer_geom">
        <mesh filename="package://yeetbot_navigation/meshes/left_hubcap.stl"/>
      </geometry>
      <material name="HubcapYellow">
        <color rgba="1.0 0.811 0.151 1.0"/>
      </material>
    </visual>
  </link>
  <gazebo reference="p3at_front_left_hub">
    <material value="Gazebo/Yellow"/>
  </gazebo>
  <joint name="base_front_left_hub_joint" type="fixed">
    <origin rpy="0 0 0" xyz="0 0.041 0"/>
    <parent link="p3at_front_left_axle"/>
    <child link="p3at_front_left_hub"/>
  </joint>
  <link name="p3at_front_left_wheel">
    <inertial>
      <mass value="1.2"/>
      <!-- 1.4 kg - axle 0.1 kg - hub 0.1 kg -->
      <origin xyz="0 0 0"/>
      <inertia ixx="0.012411765597" ixy="0" ixz="0" iyy="0.015218160428" iyz="0" izz="0.011763977943"/>
    </inertial>
    <visual>
      <origin rpy="0 0 0" xyz="0 0 0"/>
      <geometry name="pioneer_geom">
        <mesh filename="package://yeetbot_navigation/meshes/wheel.stl"/>
      </geometry>
      <material name="WheelBlack">
        <color rgba="0.117 0.117 0.117 1"/>
      </material>
    </visual>
    <collision>
      <origin rpy="-1.57079635 0 0" xyz="0 0 0"/>
      <geometry>
        <!--mesh filename="package://yeetbot_navigation/meshes/wheel.stl"/-->
        <cylinder length="0.075" radius="0.111"/>
      </geometry>
    </collision>
  </link>
  <gazebo reference="p3at_front_left_wheel">
    <material value="Gazebo/Black"/>
  </gazebo>
  <joint name="p3at_front_left_wheel_joint" type="continuous">
    <axis xyz="0 1 0"/>
    <anchor xyz="0 0 0"/>
    <limit effort="100" velocity="100"/>
    <joint_properties damping="0.7"/>
    <origin rpy="0 0 0" xyz="0 0 0"/>
    <parent link="p3at_front_left_hub"/>
    <child link="p3at_front_left_wheel"/>
  </joint>
  <!-- Back Axles + Wheels + Hubcaps -->
  <link name="p3at_back_left_axle">
    <inertial>
      <mass value="0.1"/>
      <origin xyz="0 0 0"/>
      <inertia ixx="1.0" ixy="0.0" ixz="0.0" iyy="1.0" iyz="0.0" izz="1.0"/>
    </inertial>
    <visual>
      <origin rpy="0 0 0" xyz="0 0 0"/>
      <geometry name="pioneer_geom">
        <mesh filename="package://yeetbot_navigation/meshes/axle.stl"/>
      </geometry>
      <material name="AxleGrey">
        <color rgba="0.5 0.5 0.5 1"/>
      </material>
    </visual>
    <collision>
      <origin rpy="0 0 0" xyz="0 0 0"/>
      <geometry>
        <mesh filename="package://yeetbot_navigation/meshes/axle.stl"/>
      </geometry>
    </collision>
  </link>
  <gazebo reference="p3at_back_left_axle">
    <material value="Gazebo/Grey"/>
  </gazebo>
  <joint name="p3at_back_left_axle_joint" type="fixed">
    <origin rpy="0 0 0" xyz="-0.134 0.156 0.111"/>
    <parent link="base_link"/>
    <child link="p3at_back_left_axle"/>
  </joint>
  <link name="p3at_back_left_hub">
    <inertial>
      <mass value="0.1"/>
      <origin xyz="0 0 0"/>
      <inertia ixx="1.0" ixy="0.0" ixz="0.0" iyy="1.0" iyz="0.0" izz="1.0"/>
    </inertial>
    <visual>
      <origin rpy="0 0 0" xyz="0 0 0"/>
      <geometry name="pioneer_geom">
        <mesh filename="package://yeetbot_navigation/meshes/left_hubcap.stl"/>
      </geometry>
      <material name="HubcapYellow"/>
    </visual>
    <collision>
      <origin rpy="0 0 0" xyz="0 0 0"/>
      <geometry>
        <mesh filename="package://yeetbot_navigation/meshes/left_hubcap.stl"/>
      </geometry>
    </collision>
  </link>
  <gazebo reference="p3at_back_left_hub">
    <material value="Gazebo/Yellow"/>
  </gazebo>
  <joint name="p3at_back_left_hub_joint" type="fixed">
    <origin rpy="0 0 0" xyz="-0 0.041 0"/>
    <parent link="p3at_back_left_axle"/>
    <child link="p3at_back_left_hub"/>
  </joint>
  <link name="p3at_back_left_wheel">
    <inertial>
      <mass value="1.2"/>
      <origin xyz="0 0 0"/>
      <inertia ixx="0.012411765597" ixy="0" ixz="0" iyy="0.015218160428" iyz="0" izz="0.011763977943"/>
    </inertial>
    <visual>
      <origin rpy="0 0 0" xyz="0 0 0"/>
      <geometry name="pioneer_geom">
        <mesh filename="package://yeetbot_navigation/meshes/wheel.stl"/>
      </geometry>
      <material name="WheelBlack"/>
    </visual>
    <collision>
      <origin rpy="-1.57079635 0 0" xyz="0 0 0"/>
      <geometry>
        <!--mesh filename="package://yeetbot_navigation/meshes/wheel.stl"/-->
        <cylinder length="0.075" radius="0.111"/>
      </geometry>
    </collision>
  </link>
  <gazebo reference="p3at_back_left_wheel">
    <material value="Gazebo/Black"/>
  </gazebo>
  <joint name="p3at_back_left_wheel_joint" type="continuous">
    <axis xyz="0 1 0"/>
    <anchor xyz="0 0 0"/>
    <limit effort="100" velocity="100"/>
    <joint_properties damping="0.7"/>
    <origin rpy="0 0 0" xyz="0 0 0"/>
    <parent link="p3at_back_left_hub"/>
    <child link="p3at_back_left_wheel"/>
  </joint>
  <!-- see http://gazebosim.org/tutorials/?tut=ros_urdf -->
  <gazebo reference="p3at_back_left_wheel">
    <kp>1000000.0</kp>
    <!-- kp and kd for rubber -->
    <kd>100.0</kd>
    <mu1>1.0</mu1>
    <!-- was 10 -->
    <mu2>1.0</mu2>
    <!-- how to get these into <surface><friction><ode>... ?
        slip1 0.5 /slip1 
         slip2 0 /slip2 
      -->
    <!-- fdir1 0 1 0 /fdir1 -->
    <!-- see http://github.com/MobileRobots/amr-ros-config/issues/6 -->
    <maxVel>1.0</maxVel>
    <minDepth>0.00</minDepth>
    <material value="Gazebo/Black"/>
  </gazebo>
  <gazebo reference="p3at_front_left_wheel">
    <kp>1000000.0</kp>
    <!-- kp and kd for rubber -->
    <kd>100.0</kd>
    <mu1>1.0</mu1>
    <!-- was 10 -->
    <mu2>1.0</mu2>
    <!-- how to get these into <surface><friction><ode>... ?
        slip1 0.5 /slip1 
         slip2 0 /slip2 
      -->
    <!-- fdir1 0 1 0 /fdir1 -->
    <!-- see http://github.com/MobileRobots/amr-ros-config/issues/6 -->
    <maxVel>1.0</maxVel>
    <minDepth>0.00</minDepth>
    <material value="Gazebo/Black"/>
  </gazebo>
  <!-- Front Axles + Wheels + Hubcaps -->
  <link name="p3at_front_right_axle">
    <inertial>
      <mass value="0.1"/>
      <origin xyz="0 0 0"/>
      <inertia ixx="1.0" ixy="0.0" ixz="0.0" iyy="1.0" iyz="0.0" izz="1.0"/>
    </inertial>
    <visual>
      <origin rpy="0 0 0" xyz="0 0 0"/>
      <geometry name="pioneer_geom">
        <mesh filename="package://yeetbot_navigation/meshes/axle.stl"/>
      </geometry>
      <material name="AxleGrey">
        <color rgba="0.5 0.5 0.5 1"/>
      </material>
    </visual>
  </link>
  <gazebo reference="p3at_front_right_axle">
    <material value="Gazebo/Grey"/>
  </gazebo>
  <joint name="base_front_right_axle_joint" type="fixed">
    <origin rpy="0 0 0" xyz="0.135 -0.156 0.111"/>
    <parent link="base_link"/>
    <child link="p3at_front_right_axle"/>
  </joint>
  <link name="p3at_front_right_hub">
    <inertial>
      <mass value="0.1"/>
      <origin xyz="0 0 0"/>
      <inertia ixx="1.0" ixy="0.0" ixz="0.0" iyy="1.0" iyz="0.0" izz="1.0"/>
    </inertial>
    <visual>
      <origin rpy="0 0 0" xyz="0 0 0"/>
      <geometry name="pioneer_geom">
        <mesh filename="package://yeetbot_navigation/meshes/right_hubcap.stl"/>
      </geometry>
      <material name="HubcapYellow">
        <color rgba="1.0 0.811 0.151 1.0"/>
      </material>
    </visual>
  </link>
  <gazebo reference="p3at_front_right_hub">
    <material value="Gazebo/Yellow"/>
  </gazebo>
  <joint name="base_front_right_hub_joint" type="fixed">
    <origin rpy="0 0 0" xyz="0 -0.041 0"/>
    <parent link="p3at_front_right_axle"/>
    <child link="p3at_front_right_hub"/>
  </joint>
  <link name="p3at_front_right_wheel">
    <inertial>
      <mass value="1.2"/>
      <!-- 1.4 kg - axle 0.1 kg - hub 0.1 kg -->
      <origin xyz="0 0 0"/>
      <inertia ixx="0.012411765597" ixy="0" ixz="0" iyy="0.015218160428" iyz="0" izz="0.011763977943"/>
    </inertial>
    <visual>
      <origin rpy="0 0 0" xyz="0 0 0"/>
      <geometry name="pioneer_geom">
        <mesh filename="package://yeetbot_navigation/meshes/wheel.stl"/>
      </geometry>
      <material name="WheelBlack">
        <color rgba="0.117 0.117 0.117 1"/>
      </material>
    </visual>
    <collision>
      <origin rpy="-1.57079635 0 0" xyz="0 0 0"/>
      <geometry>
        <!--mesh filename="package://yeetbot_navigation/meshes/wheel.stl"/-->
        <cylinder length="0.075" radius="0.111"/>
      </geometry>
    </collision>
  </link>
  <gazebo reference="p3at_front_right_wheel">
    <material value="Gazebo/Black"/>
  </gazebo>
  <joint name="p3at_front_right_wheel_joint" type="continuous">
    <axis xyz="0 1 0"/>
    <anchor xyz="0 0 0"/>
    <limit effort="100" velocity="100"/>
    <joint_properties damping="0.7"/>
    <origin rpy="0 0 0" xyz="0 0 0"/>
    <parent link="p3at_front_right_hub"/>
    <child link="p3at_front_right_wheel"/>
  </joint>
  <!-- Back Axles + Wheels + Hubcaps -->
  <link name="p3at_back_right_axle">
    <inertial>
      <mass value="0.1"/>
      <origin xyz="0 0 0"/>
      <inertia ixx="1.0" ixy="0.0" ixz="0.0" iyy="1.0" iyz="0.0" izz="1.0"/>
    </inertial>
    <visual>
      <origin rpy="0 0 0" xyz="0 0 0"/>
      <geometry name="pioneer_geom">
        <mesh filename="package://yeetbot_navigation/meshes/axle.stl"/>
      </geometry>
      <material name="AxleGrey">
        <color rgba="0.5 0.5 0.5 1"/>
      </material>
    </visual>
    <collision>
      <origin rpy="0 0 0" xyz="0 0 0"/>
      <geometry>
        <mesh filename="package://yeetbot_navigation/meshes/axle.stl"/>
      </geometry>
    </collision>
  </link>
  <gazebo reference="p3at_back_right_axle">
    <material value="Gazebo/Grey"/>
  </gazebo>
  <joint name="p3at_back_right_axle_joint" type="fixed">
    <origin rpy="0 0 0" xyz="-0.134 -0.156 0.111"/>
    <parent link="base_link"/>
    <child link="p3at_back_right_axle"/>
  </joint>
  <link name="p3at_back_right_hub">
    <inertial>
      <mass value="0.1"/>
      <origin xyz="0 0 0"/>
      <inertia ixx="1.0" ixy="0.0" ixz="0.0" iyy="1.0" iyz="0.0" izz="1.0"/>
    </inertial>
    <visual>
      <origin rpy="0 0 0" xyz="0 0 0"/>
      <geometry name="pioneer_geom">
        <mesh filename="package://yeetbot_navigation/meshes/right_hubcap.stl"/>
      </geometry>
      <material name="HubcapYellow"/>
    </visual>
    <collision>
      <origin rpy="0 0 0" xyz="0 0 0"/>
      <geometry>
        <mesh filename="package://yeetbot_navigation/meshes/right_hubcap.stl"/>
      </geometry>
    </collision>
  </link>
  <gazebo reference="p3at_back_right_hub">
    <material value="Gazebo/Yellow"/>
  </gazebo>
  <joint name="p3at_back_right_hub_joint" type="fixed">
    <origin rpy="0 0 0" xyz="-0 -0.041 0"/>
    <parent link="p3at_back_right_axle"/>
    <child link="p3at_back_right_hub"/>
  </joint>
  <link name="p3at_back_right_wheel">
    <inertial>
      <mass value="1.2"/>
      <origin xyz="0 0 0"/>
      <inertia ixx="0.012411765597" ixy="0" ixz="0" iyy="0.015218160428" iyz="0" izz="0.011763977943"/>
    </inertial>
    <visual>
      <origin rpy="0 0 0" xyz="0 0 0"/>
      <geometry name="pioneer_geom">
        <mesh filename="package://yeetbot_navigation/meshes/wheel.stl"/>
      </geometry>
      <material name="WheelBlack"/>
    </visual>
    <collision>
      <origin rpy="-1.57079635 0 0" xyz="0 0 0"/>
      <geometry>
        <!--mesh filename="package://yeetbot_navigation/meshes/wheel.stl"/-->
        <cylinder length="0.075" radius="0.111"/>
      </geometry>
    </collision>
  </link>
  <gazebo reference="p3at_back_right_wheel">
    <material value="Gazebo/Black"/>
  </gazebo>
  <joint name="p3at_back_right_wheel_joint" type="continuous">
    <axis xyz="0 1 0"/>
    <anchor xyz="0 0 0"/>
    <limit effort="100" velocity="100"/>
    <joint_properties damping="0.7"/>
    <origin rpy="0 0 0" xyz="0 0 0"/>
    <parent link="p3at_back_right_hub"/>
    <child link="p3at_back_right_wheel"/>
  </joint>
  <!-- see http://gazebosim.org/tutorials/?tut=ros_urdf -->
  <gazebo reference="p3at_back_right_wheel">
    <kp>1000000.0</kp>
    <!-- kp and kd for rubber -->
    <kd>100.0</kd>
    <mu1>1.0</mu1>
    <!-- was 10 -->
    <mu2>1.0</mu2>
    <!-- how to get these into <surface><friction><ode>... ?
        slip1 0.5 /slip1 
         slip2 0 /slip2 
      -->
    <!-- fdir1 0 1 0 /fdir1 -->
    <!-- see http://github.com/MobileRobots/amr-ros-config/issues/6 -->
    <maxVel>1.0</maxVel>
    <minDepth>0.00</minDepth>
    <material value="Gazebo/Black"/>
  </gazebo>
  <gazebo reference="p3at_front_right_wheel">
    <kp>1000000.0</kp>
    <!-- kp and kd for rubber -->
    <kd>100.0</kd>
    <mu1>1.0</mu1>
    <!-- was 10 -->
    <mu2>1.0</mu2>
    <!-- how to get these into <surface><friction><ode>... ?
        slip1 0.5 /slip1 
         slip2 0 /slip2 
      -->
    <!-- fdir1 0 1 0 /fdir1 -->
    <!-- see http://github.com/MobileRobots/amr-ros-config/issues/6 -->
    <maxVel>1.0</maxVel>
    <minDepth>0.00</minDepth>
    <material value="Gazebo/Black"/>
  </gazebo>
  <gazebo>
    <plugin filename="libgazebo_ros_skid_steer_drive.so" name="skid_steer_drive_controller">
      <updateRate>100.0</updateRate>
      <robotNamespace>sim_p3at</robotNamespace>
      <leftFrontJoint>p3at_front_left_wheel_joint</leftFrontJoint>
      <rightFrontJoint>p3at_front_right_wheel_joint</rightFrontJoint>
      <leftRearJoint>p3at_back_left_wheel_joint</leftRearJoint>
      <rightRearJoint>p3at_back_right_wheel_joint</rightRearJoint>
      <wheelSeparation>0.4</wheelSeparation>
      <wheelDiameter>0.215</wheelDiameter>
      <robotBaseFrame>base_link</robotBaseFrame>
      <MaxForce>5.0</MaxForce>
      <torque>200</torque>
      <commandTopic>cmd_vel</commandTopic>
      <odometryTopic>odom</odometryTopic>
      <odometryFrame>odom</odometryFrame>
      <broadcastTF>1</broadcastTF>
    </plugin>
  </gazebo>
</robot>

